<?xml version="1.0"?>
<sdf version="1.4">
  <world name="gazebo_dingo_o_empty_world">
    <include>
      <uri>model://ground_plane</uri>
    </include>
    <include>
      <uri>model://sun</uri>
    </include>

  
  <model name="dingo_o">  
  <pose>0.0 0.0 0.0 0.0 0.0 0.0</pose>
  <static>false</static>
    
    <link name="base_footprint"/>
    <link name="base_link"></link>

    <link name="chassis_link">
      <inertial>
        <pose>0.0 0.0 0.0 0.0 0.0 0.0</pose>
        <mass>14.0</mass>
        <inertia> 
          <ixx>0.35498</ixx>       
          <ixy>0.0</ixy>        
          <ixz>0.0</ixz>        
          <iyy>0.7266</iyy>       
          <iyz>0.0</iyz>         
          <izz>1.0553</izz>
        </inertia>
      </inertial>
      <collision name="collision">
        <pose>0.0 0.0 0.0 0.0 0.0 0.0</pose>
        <geometry>
          <mesh>
            <uri>/home/hossein/dingo_ws/src/dingo_simulator/dingo_gazebo/models/dingo_o/meshes/omni_chassis_collision.stl</uri>
          </mesh>
        </geometry>
      </collision>
      <visual name="visual">
        <pose>0.0 0.0 0.0 0.0 0.0 0.0</pose>
        <geometry>
          <mesh>
            <uri>/home/hossein/dingo_ws/src/dingo_simulator/dingo_gazebo/models/dingo_o/meshes/omni_chassis.dae</uri>
          </mesh>
        </geometry>
      </visual>
    </link>

    <link name="front_left_wheel_link">
      <pose>0.285 0.2104 0.035145 0.0 0.0 0.0</pose>
      <inertial>
        <pose>0.0 0.0 0.0 0.0 0.0 0.0</pose>
        <mass>0.40</mass>
        <inertia> 
          <ixx>0.0003234</ixx>       
          <ixy>0.0</ixy>        
          <ixz>0.0</ixz>        
          <iyy>0.0003234</iyy>       
          <iyz>0.0</iyz>         
          <izz>0.0004901</izz>
        </inertia>
      </inertial>
      <collision name="collision">
        <pose>0.0 0.0 0.0 1.57079632679 0.0 0.0</pose>
        <geometry>
          <cylinder>
            <radius>0.050</radius>
            <length>0.050</length>
          </cylinder>
        </geometry>
         <surface>
          <!-- TODO These data are not based on the URDF data -->
          <friction>
            <ode>
              <mu>0.5</mu>
              <mu2>0.5</mu2>
              <fdir1>1 0 0</fdir1>
            </ode>
          </friction>
          <contact>
            <ode>
              <kp>1e+7</kp>
              <kd>1</kd>
            </ode>
          </contact>
        </surface>
      </collision>
      <visual name="visual">
        <pose>0.0 0.0 0.0 1.57079632679 0.0 0.0</pose>
        <geometry>
          <cylinder>
            <radius>0.050</radius>
            <length>0.050</length>
          </cylinder>
        </geometry>
        <material>
          <ambient>0.2 0.2 0.2 1</ambient>
          <diffuse>0.2 0.2 0.2 1.0</diffuse>
          <specular>0.2 0.2 0.2 1</specular>
          <emissive>0 0 0 0</emissive>
       </material>
      </visual>
    </link>

    <link name="front_right_wheel_link">
      <pose>0.285 -0.2104 0.035145 0.0 0.0 0.0</pose>
      <inertial>
        <pose>0.0 0.0 0.0 0.0 0.0 0.0</pose>
        <mass>0.40</mass>
        <inertia> 
          <ixx>0.0003234</ixx>       
          <ixy>0.0</ixy>        
          <ixz>0.0</ixz>        
          <iyy>0.0003234</iyy>       
          <iyz>0.0</iyz>         
          <izz>0.0004901</izz>
        </inertia>
      </inertial>
      <collision name="collision">
        <pose>0.0 0.0 0.0 1.57079632679 0.0 0.0</pose>
        <geometry>
          <cylinder>
            <radius>0.050</radius>
            <length>0.050</length>
          </cylinder>
        </geometry>
         <surface>
          <!-- TODO These data are not based on the URDF data -->
          <friction>
            <ode>
              <mu>0.5</mu>
              <mu2>0.5</mu2>
              <fdir1>1 0 0</fdir1>
            </ode>
          </friction>
          <contact>
            <ode>
              <kp>1e+7</kp>
              <kd>1</kd>
            </ode>
          </contact>
        </surface>
      </collision>
      <visual name="visual">
        <pose>0.0 0.0 0.0 1.57079632679 0.0 0.0</pose>
        <geometry>
          <cylinder>
            <radius>0.050</radius>
            <length>0.050</length>
          </cylinder>
        </geometry>
        <material>
          <ambient>0.2 0.2 0.2 1</ambient>
          <diffuse>0.2 0.2 0.2 1.0</diffuse>
          <specular>0.2 0.2 0.2 1</specular>
          <emissive>0 0 0 0</emissive>
       </material>
      </visual>
    </link>

    <link name="rear_left_wheel_link">
      <pose>-0.285 0.2104 0.035145 0.0 0.0 0.0</pose>
      <inertial>
        <pose>0.0 0.0 0.0 0.0 0.0 0.0</pose>
        <mass>0.40</mass>
        <inertia> 
          <ixx>0.0003234</ixx>       
          <ixy>0.0</ixy>        
          <ixz>0.0</ixz>        
          <iyy>0.0003234</iyy>       
          <iyz>0.0</iyz>         
          <izz>0.0004901</izz>
        </inertia>
      </inertial>
      <collision name="collision">
        <pose>0.0 0.0 0.0 1.57079632679 0.0 0.0</pose>
        <geometry>
          <cylinder>
            <radius>0.050</radius>
            <length>0.050</length>
          </cylinder>
        </geometry>
         <surface>
          <!-- TODO These data are not based on the URDF data -->
          <friction>
            <ode>
              <mu>0.5</mu>
              <mu2>0.5</mu2>
              <fdir1>1 0 0</fdir1>
            </ode>
          </friction>
          <contact>
            <ode>
              <kp>1e+7</kp>
              <kd>1</kd>
            </ode>
          </contact>
        </surface>
      </collision>
      <visual name="visual">
        <pose>0.0 0.0 0.0 1.57079632679 0.0 0.0</pose>
        <geometry>
          <cylinder>
            <radius>0.050</radius>
            <length>0.050</length>
          </cylinder>
        </geometry>
        <material>
          <ambient>0.2 0.2 0.2 1</ambient>
          <diffuse>0.2 0.2 0.2 1.0</diffuse>
          <specular>0.2 0.2 0.2 1</specular>
          <emissive>0 0 0 0</emissive>
       </material>
      </visual>
    </link>

    <link name="rear_right_wheel_link">
      <pose>-0.285 -0.2104 0.035145 0.0 0.0 0.0</pose>
      <inertial>
        <pose>0.0 0.0 0.0 0.0 0.0 0.0</pose>
        <mass>0.40</mass>
        <inertia> 
          <ixx>0.0003234</ixx>       
          <ixy>0.0</ixy>        
          <ixz>0.0</ixz>        
          <iyy>0.0003234</iyy>       
          <iyz>0.0</iyz>         
          <izz>0.0004901</izz>
        </inertia>
      </inertial>
      <collision name="collision">
        <pose>0.0 0.0 0.0 1.57079632679 0.0 0.0</pose>
        <geometry>
          <cylinder>
            <radius>0.050</radius>
            <length>0.050</length>
          </cylinder>
        </geometry>
         <surface>
          <!-- TODO These data are not based on the URDF data -->
          <friction>
            <ode>
              <mu>0.5</mu>
              <mu2>0.5</mu2>
              <fdir1>1 0 0</fdir1>
            </ode>
          </friction>
          <contact>
            <ode>
              <kp>1e+7</kp>
              <kd>1</kd>
            </ode>
          </contact>
        </surface>
      </collision>
      <visual name="visual">
        <pose>0.0 0.0 0.0 1.57079632679 0.0 0.0</pose>
        <geometry>
          <cylinder>
            <radius>0.050</radius>
            <length>0.050</length>
          </cylinder>
        </geometry>
        <material>
          <ambient>0.2 0.2 0.2 1</ambient>
          <diffuse>0.2 0.2 0.2 1.0</diffuse>
          <specular>0.2 0.2 0.2 1</specular>
          <emissive>0 0 0 0</emissive>
       </material>
      </visual>
    </link>

    <link name="imu_link">
      <sensor name="dingo_imu" type="imu">
        <always_on>true</always_on>
        <update_rate>50</update_rate>
        <imu>
          <angular_velocity>
            <x>
              <noise type="gaussian">
                <mean>0.0</mean>
                <stddev>2e-4</stddev>
                <bias_mean>0.0000075</bias_mean>
                <bias_stddev>0.0000008</bias_stddev>
              </noise>
            </x>
            <y>
              <noise type="gaussian">
                <mean>0.0</mean>
                <stddev>2e-4</stddev>
                <bias_mean>0.0000075</bias_mean>
                <bias_stddev>0.0000008</bias_stddev>
              </noise>
            </y>
            <z>
              <noise type="gaussian">
                <mean>0.0</mean>
                <stddev>2e-4</stddev>
                <bias_mean>0.0000075</bias_mean>
                <bias_stddev>0.0000008</bias_stddev>
              </noise>
            </z>
          </angular_velocity>
          <linear_acceleration>
            <x>
              <noise type="gaussian">
                <mean>0.0</mean>
                <stddev>1.7e-2</stddev>
                <bias_mean>0.1</bias_mean>
                <bias_stddev>0.001</bias_stddev>
              </noise>
            </x>
            <y>
              <noise type="gaussian">
                <mean>0.0</mean>
                <stddev>1.7e-2</stddev>
                <bias_mean>0.1</bias_mean>
                <bias_stddev>0.001</bias_stddev>
              </noise>
            </y>
            <z>
              <noise type="gaussian">
                <mean>0.0</mean>
                <stddev>1.7e-2</stddev>
                <bias_mean>0.1</bias_mean>
                <bias_stddev>0.001</bias_stddev>
              </noise>
            </z>
          </linear_acceleration>
        </imu>
        <plugin name="dingo_imu" filename="libgazebo_ros_imu_sensor.so">
          <ros>
            <namespace>/imu</namespace>
            <argument>~/out:=data</argument>
          </ros>
        </plugin>
      </sensor>
    </link>



    <joint name="base_footprint_joint" type="fixed">
      <pose>0.0 0.0 0.0 0 0 0</pose>
      <parent>base_footprint</parent>
      <child>base_link</child>
    </joint>

    <joint name="base_link_joint" type="fixed">
      <pose>0.0 0.0 0.0 0 0 0</pose>
      <parent>base_link</parent>
      <child>chassis_link</child>
    </joint>

    <joint name="front_left_wheel_joint" type="revolute">
      <parent>chassis_link</parent>
      <child>front_left_wheel_link</child>
      <axis>
        <xyz>0 1 0</xyz>
      </axis>
    </joint>

    <joint name="front_right_wheel_joint" type="revolute">
      <parent>chassis_link</parent>
      <child>front_right_wheel_link</child>
      <axis>
        <xyz>0 1 0</xyz>
      </axis>
    </joint>

    <joint name="rear_left_wheel_joint" type="revolute">
      <parent>chassis_link</parent>
      <child>rear_left_wheel_link</child>
      <axis>
        <xyz>0 1 0</xyz>
      </axis>
    </joint>

    <joint name="rear_right_wheel_joint" type="revolute">
      <parent>chassis_link</parent>
      <child>rear_right_wheel_link</child>
      <axis>
        <xyz>0 1 0</xyz>
      </axis>
    </joint>

  </model>
  </world>
</sdf>
