<?xml version="1.0" ?>
<sdf version="1.5">
  <model name="dingo_d">  
  <pose>0.0 0.0 0.0 0.0 0.0 0.0</pose>
  <static>false</static>
    
    <link name="base_footprint"/>
    <link name="base_link"/>

    <link name="chassis_link">
      <inertial>
        <pose>0.0 0.0 0.0 0.0 0.0 0.0</pose>
        <mass>10.0</mass>
        <inertia> 
          <ixx>0.2216</ixx>       
          <ixy>0.0</ixy>        
          <ixz>0.0</ixz>        
          <iyy>0.2458</iyy>       
          <iyz>0.0</iyz>         
          <izz>0.4474</izz>
        </inertia>
      </inertial>
      <collision name="collision">
        <pose>0.0 0.0 0.0 0.0 0.0 0.0</pose>
        <geometry>
          <mesh>
            <uri>/home/hossein/dingo_ws/src/dingo/dingo_description/models/dingo-d/meshes/diff_chassis_collision.stl</uri>
          </mesh>
        </geometry>
      </collision>
      <visual name="visual">
        <pose>0.0 0.0 0.0 0.0 0.0 0.0</pose>
        <geometry>
          <mesh>
            <uri>/home/hossein/dingo_ws/src/dingo/dingo_description/models/dingo-d/meshes/diff_chassis.dae</uri>
          </mesh>
        </geometry>
      </visual>
    </link>


     <link name="rear_caster">
      <pose>-0.244 0.0 -0.00674 0.0 0.0 0.0</pose>
      <inertial>
        <pose>0.0 0.0 0.0 0.0 0.0 0.0</pose>
        <mass>0.10</mass>
        <inertia> 
          <ixx>0.001</ixx>       
          <ixy>0.0</ixy>        
          <ixz>0.0</ixz>        
          <iyy>0.001</iyy>       
          <iyz>0.0</iyz>         
          <izz>0.001</izz>
        </inertia>
      </inertial>
      <collision name="collision">
        <pose>0.0 0.0 0.0 0.0 0.0 0.0</pose>
        <geometry>
          <sphere>
            <radius>0.010</radius>
          </sphere>
        </geometry>
        <surface>
          <friction>
            <ode>
              <mu>0.0</mu>
              <mu2>0.0</mu2>
              <slip1>1.0</slip1>
              <slip2>1.0</slip2>
            </ode>
          </friction>
        </surface>
      </collision>
      <visual name="visual">
        <pose>0.0 0.0 0.0 0.0 0.0 0.0</pose>
        <geometry>
          <sphere>
            <radius>0.010</radius>
          </sphere>
        </geometry>
      </visual>
    </link>

    <link name="left_wheel_link">
      <pose>0.0989838 0.2261616 0.0345 0.0 0.0 0.0</pose>
      <inertial>
        <pose>0.0 0.0 0.0 0.0 0.0 0.0</pose>
        <mass>0.111</mass>
        <inertia> 
          <ixx>0.0003234</ixx>       
          <ixy>0.0</ixy>        
          <ixz>0.0</ixz>        
          <iyy>0.0003234</iyy>       
          <iyz>0.0</iyz>         
          <izz>0.00049015</izz>
        </inertia>
      </inertial>
      <collision name="collision">
        <pose>0.0 0.0 0.0 1.57079632679 0.0 0.0</pose>
        <geometry>
          <cylinder>
            <radius>0.049</radius>
            <length>0.02032</length>
          </cylinder>
        </geometry>
         <surface>
          <!-- TODO These data are not based on the URDF data -->
          <friction>
            <ode>
              <mu>0.5</mu>
              <mu2>0.5</mu2>
              <fdir1>1 0 0</fdir1>
            </ode>
          </friction>
          <contact>
            <ode>
              <kp>1e+7</kp>
              <kd>1</kd>
            </ode>
          </contact>
        </surface>
      </collision>
      <visual name="visual">
        <pose>0.0 0.0 0.0 0.0 0.0 0.0</pose>
        <geometry>
          <mesh>
            <uri>/home/hossein/dingo_ws/src/dingo/dingo_description/models/dingo-d/meshes/wheel.stl</uri>
          </mesh>
        </geometry>
      </visual>
    </link>

    <link name="right_wheel_link">
      <pose>0.0989838 -0.2261616 0.0345 0.0 0.0 0.0</pose>
      <inertial>
        <pose>0.0 0.0 0.0 0.0 0.0 0.0</pose>
        <mass>0.111</mass>
        <inertia> 
          <ixx>0.0003234</ixx>       
          <ixy>0.0</ixy>        
          <ixz>0.0</ixz>        
          <iyy>0.0003234</iyy>       
          <iyz>0.0</iyz>         
          <izz>0.00049015</izz>
        </inertia>
      </inertial>
      <collision name="collision">
        <pose>0.0 0.0 0.0 1.57079632679 0.0 0.0</pose>
        <geometry>
          <cylinder>
            <radius>0.049</radius>
            <length>0.02032</length>
          </cylinder>
        </geometry>
         <surface>
          <!-- TODO These data are not based on the URDF data -->
          <friction>
            <ode>
              <mu>0.5</mu>
              <mu2>0.5</mu2>
              <fdir1>1 0 0</fdir1>
            </ode>
          </friction>
          <contact>
            <ode>
              <kp>1e+7</kp>
              <kd>1</kd>
            </ode>
          </contact>
        </surface>
      </collision>
      <visual name="visual">
        <pose>0.0 0.0 0.0 0.0 0.0 0.0</pose>
        <geometry>
          <mesh>
            <uri>/home/hossein/dingo_ws/src/dingo/dingo_description/models/dingo-d/meshes/wheel.stl</uri>
          </mesh>
        </geometry>
      </visual>
    </link>

    <link name="imu_link">
      <sensor name="dingo_imu" type="imu">
        <always_on>true</always_on>
        <update_rate>50</update_rate>
        <imu>
          <angular_velocity>
            <x>
              <noise type="gaussian">
                <mean>0.0</mean>
                <stddev>2e-4</stddev>
                <bias_mean>0.0000075</bias_mean>
                <bias_stddev>0.0000008</bias_stddev>
              </noise>
            </x>
            <y>
              <noise type="gaussian">
                <mean>0.0</mean>
                <stddev>2e-4</stddev>
                <bias_mean>0.0000075</bias_mean>
                <bias_stddev>0.0000008</bias_stddev>
              </noise>
            </y>
            <z>
              <noise type="gaussian">
                <mean>0.0</mean>
                <stddev>2e-4</stddev>
                <bias_mean>0.0000075</bias_mean>
                <bias_stddev>0.0000008</bias_stddev>
              </noise>
            </z>
          </angular_velocity>
          <linear_acceleration>
            <x>
              <noise type="gaussian">
                <mean>0.0</mean>
                <stddev>1.7e-2</stddev>
                <bias_mean>0.1</bias_mean>
                <bias_stddev>0.001</bias_stddev>
              </noise>
            </x>
            <y>
              <noise type="gaussian">
                <mean>0.0</mean>
                <stddev>1.7e-2</stddev>
                <bias_mean>0.1</bias_mean>
                <bias_stddev>0.001</bias_stddev>
              </noise>
            </y>
            <z>
              <noise type="gaussian">
                <mean>0.0</mean>
                <stddev>1.7e-2</stddev>
                <bias_mean>0.1</bias_mean>
                <bias_stddev>0.001</bias_stddev>
              </noise>
            </z>
          </linear_acceleration>
        </imu>
        <plugin name="dingo_imu" filename="libgazebo_ros_imu_sensor.so">
          <ros>
            <namespace>/imu</namespace>
            <argument>~/out:=data</argument>
          </ros>
        </plugin>
      </sensor>
    </link>

   <link name="front_laser">
      <pose>0.200 0.0 0.064263 0 0 0</pose>
      <collision name="lidar_sensor_collision">
        <pose>0.0 0 0.0 0 0 0</pose>
        <geometry>
          <cylinder>
            <radius>0.0508</radius>
            <length>0.055</length>
          </cylinder>
        </geometry>
      </collision>

      <visual name="lidar_sensor_visual">
        <pose>0.0 0 0.0 0 0 0</pose>
        <geometry>
          <mesh>
            <uri>/home/hossein/dingo_ws/src/dingo/dingo_description/meshes/hokuyo_ust10.stl</uri>
          </mesh>
        </geometry>
      </visual>
      <!-- feel free to change the ray parameters based on your lidar spec -->
      <sensor name="hls_lfcd_lds" type="ray">
        <always_on>true</always_on>
        <visualize>false</visualize>
        <pose>0.0 0 0.05 0 0 0</pose>
        <update_rate>20</update_rate>
        <ray>
          <scan>
            <horizontal>
              <samples>720</samples>
              <resolution>1.000000</resolution>
              <min_angle>0.000000</min_angle>
              <max_angle>6.280000</max_angle>
            </horizontal>
          </scan>
          <range>
            <min>0.10000</min>
            <max>10.0</max>
            <resolution>0.01000</resolution>
          </range>
          <noise>
            <type>gaussian</type>
            <mean>0.0</mean>
            <stddev>0.001</stddev>
          </noise>
        </ray>
        <plugin name="dingo_laserscan" filename="libgazebo_ros_ray_sensor.so">
          <ros>
            <remapping>~/out:=scan</remapping>
          </ros>
          <output_type>sensor_msgs/LaserScan</output_type>
          <frame_name>front_laser</frame_name>
        </plugin>
      </sensor>
    </link>

    <link name="front_laser_mount">
      <pose>0.200 0.0 0.064263 0 0 0</pose>
    </link>

    <joint name="base_footprint_joint" type="fixed">
      <parent>base_footprint</parent>
      <child>base_link</child>
      <pose>0.0 0.0 0.0 0 0 0</pose>
    </joint>

    <joint name="base_link_joint" type="fixed">
      <parent>base_link</parent>
      <child>chassis_link</child>
      <pose>0.0 0.0 0.0 0 0 0</pose>
    </joint>

    <joint name="left_wheel_joint" type="revolute">
      <parent>chassis_link</parent>
      <child>left_wheel_link</child>
      <axis>
        <xyz>0 1 0</xyz>
      </axis>
    </joint>


    <joint name="right_wheel_joint" type="revolute">
      <parent>chassis_link</parent>
      <child>right_wheel_link</child>
      <axis>
        <xyz>0 1 0</xyz>
      </axis>
    </joint>


    <joint name='rear_caster_joint' type='fixed'>
      <parent>chassis_link</parent>
      <child>rear_caster</child>
    </joint>


    <joint name="imu_joint" type="fixed">
      <parent>chassis_link</parent>
      <child>imu_link</child>
    </joint>

    <joint name="front_laser_mount_joint" type="fixed">
      <parent>front_mount</parent>
      <child>front_laser_mount</child>
    </joint>

    <joint name="lidar_joint" type="fixed">
      <parent>front_laser_mount</parent>
      <child>front_laser</child>
    </joint>
    <!--
    Mounting points for accessories in the top channel.
    These are flush with the top of the robot and all oriented to face forwards.
    Dingo-D has 6 evenly-spaced 80mm mounts
    We name the mounts (from front to back)
      - front
      - front b
      - front c
      - rear c
      - rear b
      - rear
    -->
    <link name="front_mount">
      <pose>0.200 0.0 0.064263 0 0 0</pose> 
    </link>
    <link name="front_b_mount">
      <pose>0.120 0.0 0.064263 0 0 0</pose>
    </link>
    <link name="front_c_mount">
      <pose>0.040 0.0 0.064263 0 0 0</pose>
    </link>
    <link name="rear_mount">
      <pose>-0.080 0.0 0.064263 0 0 0</pose>
    </link>
    <link name="rear_b_mount">
      <pose>-0.15 0.0 0.064263 0 0 0</pose>
    </link>
    <link name="rear_c_mount">
      <pose>-0.24 0 0.064263 0 0 0</pose>
    </link>

    <joint name="front_c_mount_joint" type="fixed">
      <parent>chassis_link</parent>
      <child>front_c_mount</child>
    </joint>
    <joint name="front_b_mount_joint" type="fixed">
      <parent>front_c_mount</parent>
      <child>front_b_mount</child>
    </joint>
    <joint name="front_mount_joint" type="fixed">
      <parent>front_b_mount</parent>
      <child>front_mount</child>
    </joint>
    <joint name="rear_c_mount_joint" type="fixed">
      <parent>chassis_link</parent>
      <child>rear_c_mount</child>
    </joint>
    <joint name="rear_b_mount_joint" type="fixed">
      <parent>rear_c_mount</parent>
      <child>rear_b_mount</child>
    </joint>
    <joint name="rear_mount_joint" type="fixed">
      <parent>rear_b_mount</parent>
      <child>rear_mount</child>
    </joint>

    <!--
      Mounting point for accessories on the front bumper.
      Use with caution, but thin sensors (e.g Raspberry Pi NoIR camera) could
      be mounted here for low-budget, front-facing capabilities
    -->
    <link name="front_bumper_mount">
      <pose>0.274 0 0.0345125 0 0 0</pose>
    </link>
    <joint name="front_bumper_mount_joint" type="fixed">
      <parent>chassis_link</parent>
      <child>front_bumper_mount</child>
    </joint>



    <plugin name="dingo_d_drive" filename="libgazebo_ros_diff_drive.so">

      <ros>
      </ros>
      <update_rate>30</update_rate>

      <left_joint>left_wheel_joint</left_joint>
      <right_joint>right_wheel_joint</right_joint>

      <wheel_separation>0.4523</wheel_separation>
      <wheel_diameter>0.098</wheel_diameter>

      <max_wheel_torque>40</max_wheel_torque>
      <max_wheel_acceleration>2.0</max_wheel_acceleration>

      <command_topic>cmd_vel</command_topic>

      <publish_odom>true</publish_odom>
      <publish_odom_tf>true</publish_odom_tf>
      <publish_wheel_tf>false</publish_wheel_tf>

      <odometry_topic>odom</odometry_topic>
      <odometry_frame>odom</odometry_frame>
      <robot_base_frame>base_footprint</robot_base_frame>

    </plugin>

    <plugin name="dingo_d_joint_state" filename="libgazebo_ros_joint_state_publisher.so">
      <ros>
        <remapping>~/out:=joint_states</remapping>
      </ros>
      <update_rate>30</update_rate>
      <joint_name>left_wheel_joint</joint_name>
      <joint_name>right_wheel_joint</joint_name>
    </plugin>    

    
  </model>
</sdf>
